Workbook

Sheet KEY
A1: Projects | C1: Sub Color | D1: Subcontractors | E1: Capacity | F1: Scope 1 | G1: Scope 2 | H1: Scope 3 | I1: Scope 4 | J1: Scope 5 | K1: Scope 6 | L1: Scope 7
A2: 1 | D2: 3C Concrete | E2: 1 | F2: Footer | G2: Slab | H2: Driveway
A3: 2 | D3: Willett & Assoc. | F3: Estimate | G3: Clearing | H3: Site Prep | I3: Rough grade | J3: Rock work
A4: 3 | D4: Julio H | F4: Block | G4: Brick | H4: Stone
A5: 4 | D5: Gerardo | F5: Framing | G5: Siding
D6: Rod Smith | F6: Roofing
D7: Dave Kaler | F7: Electrical Pre | G7: Electrical Rough | H7: Electrical Finish | I7: Appliances
D8: Adco | F8: HVAC Pre | G8: HVAC Rough | H8: HVAC Finish
D9: Hays | E9: 1 | F9: Plumbing Pre | G9: Plumbing Rough | H9: Plumbing Finish
D10: LW Contracting | F10: Flooring | G10: Tile Work
D11: Tyler Champion | F11: Insulation Block | G11: Insulation Walls | H11: Insulation Ceiling
D12: Bernall Constr. | F12: Sheetrock
D13: Danny Liedecher | F13: Garage Doors
D14: BlueGrass Gutters | F14: Gutters
D15: Matt Thorne | E15: 1 | F15: Trim Interior | G15: Trim Exterior
D16: L&L Painting | F16: Painting Primer | G16: Painting Main | H16: Painting Finish
D17: Whittmer | F17: Cabinets
D18: Tate Granit | F18: Countertops
D19: Angie Mullens | F19: Closets
D20: Jacob Hayden | F20: Landscaping | G20: Finish Grade | H20: French Drain | I20: Gutter Drains
D21: Ramiro | F21: Irrigation
D22: TruGreen | F22: Lawn Seeding
D23: Angies Cleaning | F23: Cleaning

Sheet Gantt
I1: 46117 | P1: 46124 | W1: 46131 | AD1: 46138 | AK1: 46145 | AR1: 46152 | AY1: 46159 | BF1: 46166 | BM1: 46173 | BT1: 46180 | CA1: 46187 | CH1: 46194 | CO1: 46201 | CV1: 46208 | DC1: 46215 | DJ1: 46222 | DQ1: 46229 | DX1: 46236 | EE1: 46243 | EL1: 46250 | ES1: 46257 | EZ1: 46264 | FG1: 46271 | FN1: 46278 | FU1: 46285 | GB1: 46292 | GI1: 46299 | GP1: 46306 | GW1: 46313 | HD1: 46320 | HK1: 46327 | HR1: 46334 | HY1: 46341 | IF1: 46348 | IM1: 46355 | IT1: 46362 | JA1: 46369 | JH1: 46376 | JO1: 46383 | JV1: 46390 | KC1: 46397 | KJ1: 46404 | KQ1: 46411 | KX1: 46418 | LE1: 46425 | LL1: 46432 | LS1: 46439 | LZ1: 46446 | MG1: 46453 | MN1: 46460 | MU1: 46467
E2: Days | I2: M | J2: T | K2: W | L2: TH | M2: F | N2: S | O2: S | P2: M | Q2: T | R2: W | S2: TH | T2: F | U2: S | V2: S | W2: M | X2: T | Y2: W | Z2: TH | AA2: F | AB2: S | AC2: S | AD2: M | AE2: T | AF2: W | AG2: TH | AH2: F | AI2: S | AJ2: S | AK2: M | AL2: T | AM2: W | AN2: TH | AO2: F | AP2: S | AQ2: S | AR2: M | AS2: T | AT2: W | AU2: TH | AV2: F | AW2: S | AX2: S | AY2: M | AZ2: T | BA2: W | BB2: TH | BC2: F | BD2: S | BE2: S | BF2: M | BG2: T | BH2: W | BI2: TH | BJ2: F | BK2: S | BL2: S | BM2: M | BN2: T | BO2: W | BP2: TH | BQ2: F | BR2: S | BS2: S | BT2: M | BU2: T | BV2: W | BW2: TH | BX2: F | BY2: S | BZ2: S | CA2: M | CB2: T | CC2: W | CD2: TH | CE2: F | CF2: S | CG2: S | CH2: M | CI2: T | CJ2: W | CK2: TH | CL2: F | CM2: S | CN2: S | CO2: M | CP2: T | CQ2: W | CR2: TH | CS2: F | CT2: S | CU2: S | CV2: M | CW2: T | CX2: W | CY2: TH | CZ2: F | DA2: S | DB2: S | DC2: M | DD2: T | DE2: W | DF2: TH | DG2: F | DH2: S | DI2: S | DJ2: M | DK2: T | DL2: W | DM2: TH | DN2: F | DO2: S | DP2: S | DQ2: M | DR2: T | DS2: W | DT2: TH | DU2: F | DV2: S | DW2: S | DX2: M | DY2: T | DZ2: W | EA2: TH | EB2: F | EC2: S | ED2: S | EE2: M | EF2: T | EG2: W | EH2: TH | EI2: F | EJ2: S | EK2: S | EL2: M | EM2: T | EN2: W | EO2: TH | EP2: F | EQ2: S | ER2: S | ES2: M | ET2: T | EU2: W | EV2: TH | EW2: F | EX2: S | EY2: S | EZ2: M | FA2: T | FB2: W | FC2: TH | FD2: F | FE2: S | FF2: S | FG2: M | FH2: T | FI2: W | FJ2: TH | FK2: F | FL2: S | FM2: S | FN2: M | FO2: T | FP2: W | FQ2: TH | FR2: F | FS2: S | FT2: S | FU2: M | FV2: T | FW2: W | FX2: TH | FY2: F | FZ2: S | GA2: S | GB2: M | GC2: T | GD2: W | GE2: TH | GF2: F | GG2: S | GH2: S | GI2: M | GJ2: T | GK2: W | GL2: TH | GM2: F | GN2: S | GO2: S | GP2: M | GQ2: T | GR2: W | GS2: TH | GT2: F | GU2: S | GV2: S | GW2: M | GX2: T | GY2: W | GZ2: TH | HA2: F | HB2: S | HC2: S | HD2: M | HE2: T | HF2: W | HG2: TH | HH2: F | HI2: S | HJ2: S | HK2: M | HL2: T | HM2: W | HN2: TH | HO2: F | HP2: S | HQ2: S | HR2: M | HS2: T | HT2: W | HU2: TH | HV2: F | HW2: S | HX2: S | HY2: M | HZ2: T | IA2: W | IB2: TH | IC2: F | ID2: S | IE2: S | IF2: M | IG2: T | IH2: W | II2: TH | IJ2: F | IK2: S | IL2: S | IM2: M | IN2: T | IO2: W | IP2: TH | IQ2: F | IR2: S | IS2: S | IT2: M | IU2: T | IV2: W | IW2: TH | IX2: F | IY2: S | IZ2: S | JA2: M | JB2: T | JC2: W | JD2: TH | JE2: F | JF2: S | JG2: S | JH2: M | JI2: T | JJ2: W | JK2: TH | JL2: F | JM2: S | JN2: S | JO2: M | JP2: T | JQ2: W | JR2: TH | JS2: F | JT2: S | JU2: S | JV2: M | JW2: T | JX2: W | JY2: TH | JZ2: F | KA2: S | KB2: S | KC2: M | KD2: T | KE2: W | KF2: TH | KG2: F | KH2: S | KI2: S | KJ2: M | KK2: T | KL2: W | KM2: TH | KN2: F | KO2: S | KP2: S | KQ2: M | KR2: T | KS2: W | KT2: TH | KU2: F | KV2: S | KW2: S | KX2: M | KY2: T | KZ2: W | LA2: TH | LB2: F | LC2: S | LD2: S | LE2: M | LF2: T | LG2: W | LH2: TH | LI2: F | LJ2: S | LK2: S | LL2: M | LM2: T | LN2: W | LO2: TH | LP2: F | LQ2: S | LR2: S | LS2: M | LT2: T | LU2: W | LV2: TH | LW2: F | LX2: S | LY2: S | LZ2: M | MA2: T | MB2: W | MC2: TH | MD2: F | ME2: S | MF2: S | MG2: M | MH2: T | MI2: W | MJ2: TH | MK2: F | ML2: S | MM2: S | MN2: M | MO2: T | MP2: W | MQ2: TH | MR2: F | MS2: S | MT2: S | MU2: M | MV2: T | MW2: W | MX2: TH | MY2: F | MZ2: S | NA2: S
A3: Project | B3: Subcontractor | C3: Scope | D3: Start Date | E3: To Complete | F3: End Date | G3: Dependancy | I3: 46111 | J3: 46112 | K3: 46113 | L3: 46114 | M3: 46115 | N3: 46116 | O3: 46117 | P3: 46118 | Q3: 46119 | R3: 46120 | S3: 46121 | T3: 46122 | U3: 46123 | V3: 46124 | W3: 46125 | X3: 46126 | Y3: 46127 | Z3: 46128 | AA3: 46129 | AB3: 46130 | AC3: 46131 | AD3: 46132 | AE3: 46133 | AF3: 46134 | AG3: 46135 | AH3: 46136 | AI3: 46137 | AJ3: 46138 | AK3: 46139 | AL3: 46140 | AM3: 46141 | AN3: 46142 | AO3: 46143 | AP3: 46144 | AQ3: 46145 | AR3: 46146 | AS3: 46147 | AT3: 46148 | AU3: 46149 | AV3: 46150 | AW3: 46151 | AX3: 46152 | AY3: 46153 | AZ3: 46154 | BA3: 46155 | BB3: 46156 | BC3: 46157 | BD3: 46158 | BE3: 46159 | BF3: 46160 | BG3: 46161 | BH3: 46162 | BI3: 46163 | BJ3: 46164 | BK3: 46165 | BL3: 46166 | BM3: 46167 | BN3: 46168 | BO3: 46169 | BP3: 46170 | BQ3: 46171 | BR3: 46172 | BS3: 46173 | BT3: 46174 | BU3: 46175 | BV3: 46176 | BW3: 46177 | BX3: 46178 | BY3: 46179 | BZ3: 46180 | CA3: 46181 | CB3: 46182 | CC3: 46183 | CD3: 46184 | CE3: 46185 | CF3: 46186 | CG3: 46187 | CH3: 46188 | CI3: 46189 | CJ3: 46190 | CK3: 46191 | CL3: 46192 | CM3: 46193 | CN3: 46194 | CO3: 46195 | CP3: 46196 | CQ3: 46197 | CR3: 46198 | CS3: 46199 | CT3: 46200 | CU3: 46201 | CV3: 46202 | CW3: 46203 | CX3: 46204 | CY3: 46205 | CZ3: 46206 | DA3: 46207 | DB3: 46208 | DC3: 46209 | DD3: 46210 | DE3: 46211 | DF3: 46212 | DG3: 46213 | DH3: 46214 | DI3: 46215 | DJ3: 46216 | DK3: 46217 | DL3: 46218 | DM3: 46219 | DN3: 46220 | DO3: 46221 | DP3: 46222 | DQ3: 46223 | DR3: 46224 | DS3: 46225 | DT3: 46226 | DU3: 46227 | DV3: 46228 | DW3: 46229 | DX3: 46230 | DY3: 46231 | DZ3: 46232 | EA3: 46233 | EB3: 46234 | EC3: 46235 | ED3: 46236 | EE3: 46237 | EF3: 46238 | EG3: 46239 | EH3: 46240 | EI3: 46241 | EJ3: 46242 | EK3: 46243 | EL3: 46244 | EM3: 46245 | EN3: 46246 | EO3: 46247 | EP3: 46248 | EQ3: 46249 | ER3: 46250 | ES3: 46251 | ET3: 46252 | EU3: 46253 | EV3: 46254 | EW3: 46255 | EX3: 46256 | EY3: 46257 | EZ3: 46258 | FA3: 46259 | FB3: 46260 | FC3: 46261 | FD3: 46262 | FE3: 46263 | FF3: 46264 | FG3: 46265 | FH3: 46266 | FI3: 46267 | FJ3: 46268 | FK3: 46269 | FL3: 46270 | FM3: 46271 | FN3: 46272 | FO3: 46273 | FP3: 46274 | FQ3: 46275 | FR3: 46276 | FS3: 46277 | FT3: 46278 | FU3: 46279 | FV3: 46280 | FW3: 46281 | FX3: 46282 | FY3: 46283 | FZ3: 46284 | GA3: 46285 | GB3: 46286 | GC3: 46287 | GD3: 46288 | GE3: 46289 | GF3: 46290 | GG3: 46291 | GH3: 46292 | GI3: 46293 | GJ3: 46294 | GK3: 46295 | GL3: 46296 | GM3: 46297 | GN3: 46298 | GO3: 46299 | GP3: 46300 | GQ3: 46301 | GR3: 46302 | GS3: 46303 | GT3: 46304 | GU3: 46305 | GV3: 46306 | GW3: 46307 | GX3: 46308 | GY3: 46309 | GZ3: 46310 | HA3: 46311 | HB3: 46312 | HC3: 46313 | HD3: 46314 | HE3: 46315 | HF3: 46316 | HG3: 46317 | HH3: 46318 | HI3: 46319 | HJ3: 46320 | HK3: 46321 | HL3: 46322 | HM3: 46323 | HN3: 46324 | HO3: 46325 | HP3: 46326 | HQ3: 46327 | HR3: 46328 | HS3: 46329 | HT3: 46330 | HU3: 46331 | HV3: 46332 | HW3: 46333 | HX3: 46334 | HY3: 46335 | HZ3: 46336 | IA3: 46337 | IB3: 46338 | IC3: 46339 | ID3: 46340 | IE3: 46341 | IF3: 46342 | IG3: 46343 | IH3: 46344 | II3: 46345 | IJ3: 46346 | IK3: 46347 | IL3: 46348 | IM3: 46349 | IN3: 46350 | IO3: 46351 | IP3: 46352 | IQ3: 46353 | IR3: 46354 | IS3: 46355 | IT3: 46356 | IU3: 46357 | IV3: 46358 | IW3: 46359 | IX3: 46360 | IY3: 46361 | IZ3: 46362 | JA3: 46363 | JB3: 46364 | JC3: 46365 | JD3: 46366 | JE3: 46367 | JF3: 46368 | JG3: 46369 | JH3: 46370 | JI3: 46371 | JJ3: 46372 | JK3: 46373 | JL3: 46374 | JM3: 46375 | JN3: 46376 | JO3: 46377 | JP3: 46378 | JQ3: 46379 | JR3: 46380 | JS3: 46381 | JT3: 46382 | JU3: 46383 | JV3: 46384 | JW3: 46385 | JX3: 46386 | JY3: 46387 | JZ3: 46388 | KA3: 46389 | KB3: 46390 | KC3: 46391 | KD3: 46392 | KE3: 46393 | KF3: 46394 | KG3: 46395 | KH3: 46396 | KI3: 46397 | KJ3: 46398 | KK3: 46399 | KL3: 46400 | KM3: 46401 | KN3: 46402 | KO3: 46403 | KP3: 46404 | KQ3: 46405 | KR3: 46406 | KS3: 46407 | KT3: 46408 | KU3: 46409 | KV3: 46410 | KW3: 46411 | KX3: 46412 | KY3: 46413 | KZ3: 46414 | LA3: 46415 | LB3: 46416 | LC3: 46417 | LD3: 46418 | LE3: 46419 | LF3: 46420 | LG3: 46421 | LH3: 46422 | LI3: 46423 | LJ3: 46424 | LK3: 46425 | LL3: 46426 | LM3: 46427 | LN3: 46428 | LO3: 46429 | LP3: 46430 | LQ3: 46431 | LR3: 46432 | LS3: 46433 | LT3: 46434 | LU3: 46435 | LV3: 46436 | LW3: 46437 | LX3: 46438 | LY3: 46439 | LZ3: 46440 | MA3: 46441 | MB3: 46442 | MC3: 46443 | MD3: 46444 | ME3: 46445 | MF3: 46446 | MG3: 46447 | MH3: 46448 | MI3: 46449 | MJ3: 46450 | MK3: 46451 | ML3: 46452 | MM3: 46453 | MN3: 46454 | MO3: 46455 | MP3: 46456 | MQ3: 46457 | MR3: 46458 | MS3: 46459 | MT3: 46460 | MU3: 46461 | MV3: 46462 | MW3: 46463 | MX3: 46464 | MY3: 46465 | MZ3: 46466 | NA3: 46467
A4: IW10 | B4: {=IFERROR(INDEX(KEY!$D$2:$D$23, MATCH(TRUE(), _xlfn.byrow(KEY!$F$2:$I$23, _xlfn.lambda(_xlpm.r, COUNTIF(_xlpm.r, C4)>0)), 0)), "")} | C4: Estimate | D4: 46113 | E4: 10 | F4: =WORKDAY(D4,E4-1) -> 46126
B5: {=IFERROR(INDEX(KEY!$D$2:$D$23, MATCH(TRUE(), _xlfn.byrow(KEY!$F$2:$I$23, _xlfn.lambda(_xlpm.r, COUNTIF(_xlpm.r, C5)>0)), 0)), "")} | C5: Clearing | D5: =_xlfn.XLOOKUP(G5,$C:$C,$F:$F)+1 -> 46127 | E5: 3 | F5: =WORKDAY(D5,E5-1) -> 46129 | G5: Estimate
B6: {=IFERROR(INDEX(KEY!$D$2:$D$23, MATCH(TRUE(), _xlfn.byrow(KEY!$F$2:$I$23, _xlfn.lambda(_xlpm.r, COUNTIF(_xlpm.r, C6)>0)), 0)), "")} | C6: Site Prep | D6: =_xlfn.XLOOKUP(G6,$C:$C,$F:$F)+1 -> 46130 | E6: 2 | F6: =WORKDAY(D6,E6-1) -> 46132 | G6: Clearing
B7: {=IFERROR(INDEX(KEY!$D$2:$D$23, MATCH(TRUE(), _xlfn.byrow(KEY!$F$2:$I$23, _xlfn.lambda(_xlpm.r, COUNTIF(_xlpm.r, C7)>0)), 0)), "")} | C7: Footer | D7: =_xlfn.XLOOKUP(G7,$C:$C,$F:$F)+1 -> 46133 | E7: 4 | F7: =WORKDAY(D7,E7-1) -> 46136 | G7: Site Prep
B8: {=IFERROR(INDEX(KEY!$D$2:$D$23, MATCH(TRUE(), _xlfn.byrow(KEY!$F$2:$I$23, _xlfn.lambda(_xlpm.r, COUNTIF(_xlpm.r, C8)>0)), 0)), "")} | C8: Block | D8: =_xlfn.XLOOKUP(G8,$C:$C,$F:$F)+1 -> 46137 | E8: 10 | F8: =WORKDAY(D8,E8-1) -> 46149 | G8: Footer
B9: {=IFERROR(INDEX(KEY!$D$2:$D$23, MATCH(TRUE(), _xlfn.byrow(KEY!$F$2:$I$23, _xlfn.lambda(_xlpm.r, COUNTIF(_xlpm.r, C9)>0)), 0)), "")} | C9: French Drain | D9: =_xlfn.XLOOKUP(G9,$C:$C,$F:$F)+1 -> 46150 | E9: 2 | F9: =WORKDAY(D9,E9-1) -> 46153 | G9: Block
B10: {=IFERROR(INDEX(KEY!$D$2:$D$23, MATCH(TRUE(), _xlfn.byrow(KEY!$F$2:$T$23, _xlfn.lambda(_xlpm.r, COUNTIF(_xlpm.r, C10)>0)), 0)), "")} | C10: Insulation Block | D10: =_xlfn.XLOOKUP(G10,$C:$C,$F:$F)+1 -> 46150 | E10: 2 | F10: =WORKDAY(D10,E10-1) -> 46153 | G10: Block
B11: {=IFERROR(INDEX(KEY!$D$2:$D$23, MATCH(TRUE(), _xlfn.byrow(KEY!$F$2:$T$23, _xlfn.lambda(_xlpm.r, COUNTIF(_xlpm.r, C11)>0)), 0)), "")} | C11: Rock Work | D11: =_xlfn.XLOOKUP(G11,$C:$C,$F:$F)+1 -> 46154 | E11: 2 | F11: =WORKDAY(D11,E11-1) -> 46155 | G11: Insulation Block
B12: {=IFERROR(INDEX(KEY!$D$2:$D$23, MATCH(TRUE(), _xlfn.byrow(KEY!$F$2:$I$23, _xlfn.lambda(_xlpm.r, COUNTIF(_xlpm.r, C12)>0)), 0)), "")} | C12: HVAC Pre | D12: =_xlfn.XLOOKUP(G12,$C:$C,$F:$F)+1 -> 46156 | E12: 2 | F12: =WORKDAY(D12,E12-1) -> 46157 | G12: Rock Work
B13: {=IFERROR(INDEX(KEY!$D$2:$D$23, MATCH(TRUE(), _xlfn.byrow(KEY!$F$2:$I$23, _xlfn.lambda(_xlpm.r, COUNTIF(_xlpm.r, C13)>0)), 0)), "")} | C13: Plumbing Pre | D13: =_xlfn.XLOOKUP(G13,$C:$C,$F:$F)+1 -> 46156 | E13: 5 | F13: =WORKDAY(D13,E13-1) -> 46162 | G13: Rock Work
B14: {=IFERROR(INDEX(KEY!$D$2:$D$23, MATCH(TRUE(), _xlfn.byrow(KEY!$F$2:$I$23, _xlfn.lambda(_xlpm.r, COUNTIF(_xlpm.r, C14)>0)), 0)), "")} | C14: Electrical Pre | D14: =_xlfn.XLOOKUP(G14,$C:$C,$F:$F)+1 -> 46156 | E14: 2 | F14: =WORKDAY(D14,E14-1) -> 46157 | G14: Rock Work
B15: {=IFERROR(INDEX(KEY!$D$2:$D$23, MATCH(TRUE(), _xlfn.byrow(KEY!$F$2:$I$23, _xlfn.lambda(_xlpm.r, COUNTIF(_xlpm.r, C15)>0)), 0)), "")} | C15: Slab | D15: =_xlfn.XLOOKUP(G15,$C:$C,$F:$F)+1 -> 46163 | E15: 4 | F15: =WORKDAY(D15,E15-1) -> 46168 | G15: Plumbing Pre
B16: {=IFERROR(INDEX(KEY!$D$2:$D$23, MATCH(TRUE(), _xlfn.byrow(KEY!$F$2:$I$23, _xlfn.lambda(_xlpm.r, COUNTIF(_xlpm.r, C16)>0)), 0)), "")} | C16: Framing | D16: =_xlfn.XLOOKUP(G16,$C:$C,$F:$F)+1 -> 46169 | E16: 30 | F16: =WORKDAY(D16,E16-1) -> 46210 | G16: Slab
B17: {=IFERROR(INDEX(KEY!$D$2:$D$23, MATCH(TRUE(), _xlfn.byrow(KEY!$F$2:$I$23, _xlfn.lambda(_xlpm.r, COUNTIF(_xlpm.r, C17)>0)), 0)), "")} | C17: Roofing | D17: =_xlfn.XLOOKUP(G17,$C:$C,$F:$F)+1 -> 46211 | E17: 4 | F17: =WORKDAY(D17,E17-1) -> 46216 | G17: Framing
B18: {=IFERROR(INDEX(KEY!$D$2:$D$23, MATCH(TRUE(), _xlfn.byrow(KEY!$F$2:$I$23, _xlfn.lambda(_xlpm.r, COUNTIF(_xlpm.r, C18)>0)), 0)), "")} | C18: Brick | D18: =_xlfn.XLOOKUP(G18,$C:$C,$F:$F)+1 -> 46217 | E18: 20 | F18: =WORKDAY(D18,E18-1) -> 46244 | G18: Roofing
B19: {=IFERROR(INDEX(KEY!$D$2:$D$23, MATCH(TRUE(), _xlfn.byrow(KEY!$F$2:$I$23, _xlfn.lambda(_xlpm.r, COUNTIF(_xlpm.r, C19)>0)), 0)), "")} | C19: Stone | D19: =_xlfn.XLOOKUP(G19,$C:$C,$F:$F)+1 -> 46217 | E19: 20 | F19: =WORKDAY(D19,E19-1) -> 46244 | G19: Roofing
B20: {=IFERROR(INDEX(KEY!$D$2:$D$23, MATCH(TRUE(), _xlfn.byrow(KEY!$F$2:$I$23, _xlfn.lambda(_xlpm.r, COUNTIF(_xlpm.r, C20)>0)), 0)), "")} | C20: Siding | D20: =_xlfn.XLOOKUP(G20,$C:$C,$F:$F)+1 -> 46217 | E20: 20 | F20: =WORKDAY(D20,E20-1) -> 46244 | G20: Roofing
B21: {=IFERROR(INDEX(KEY!$D$2:$D$23, MATCH(TRUE(), _xlfn.byrow(KEY!$F$2:$I$23, _xlfn.lambda(_xlpm.r, COUNTIF(_xlpm.r, C21)>0)), 0)), "")} | C21: Rough Grade | D21: =_xlfn.XLOOKUP(G21,$C:$C,$F:$F)+1 -> 46245 | E21: 2 | F21: =WORKDAY(D21,E21-1) -> 46246 | G21: Brick
B22: {=IFERROR(INDEX(KEY!$D$2:$D$23, MATCH(TRUE(), _xlfn.byrow(KEY!$F$2:$I$23, _xlfn.lambda(_xlpm.r, COUNTIF(_xlpm.r, C22)>0)), 0)), "")} | C22: Irrigation | D22: =_xlfn.XLOOKUP(G22,$C:$C,$F:$F)+1 -> 46247 | E22: 2 | F22: =WORKDAY(D22,E22-1) -> 46248 | G22: Rough Grade
B23: {=IFERROR(INDEX(KEY!$D$2:$D$23, MATCH(TRUE(), _xlfn.byrow(KEY!$F$2:$I$23, _xlfn.lambda(_xlpm.r, COUNTIF(_xlpm.r, C23)>0)), 0)), "")} | C23: Finish Grade | D23: =_xlfn.XLOOKUP(G23,$C:$C,$F:$F)+1 -> 46249 | E23: 2 | F23: =WORKDAY(D23,E23-1) -> 46251 | G23: Irrigation
... B47: {=IFERROR(INDEX(KEY!$D$2:$D$23, MATCH(TRUE(), _xlfn.byrow(KEY!$F$2:$I$23, _xlfn.lambda(_xlpm.r, COUNTIF(_xlpm.r, C47)>0)), 0)), "")} | C47: Cleaning | D47: =_xlfn.XLOOKUP(G47,$C:$C,$F:$F)+1 -> 46290 | E47: 3 | F47: =WORKDAY(D47,E47-1) -> 46294 | G47: Painting Finish
E49: =F47-D4 -> 181 | F49: Estimate to cleaning
E50: =F47-D5 -> 167 | F50: Days to build
E51: =E50/30.41 -> 5.4916146 | F51: Months to build

Sheet Projects
A1: Project | B1: Start Date | C1: Notes | E1: How to use
A2: IW10 | B2: 46113 | C2: Base project from original schedule | E2: 1) Edit project start dates here.
A3: IW11 | B3: 46134 | C3: Edit this start date | E3: 2) Edit task durations in Schedule Engine column K.
A4: IW12 | B4: 46155 | C4: Edit this start date | E4: 3) Calculated Start/Finish update automatically.
A5: IW13 | B5: 46176 | C5: Future slot | E5: 4) Red bars/load cells mean bottleneck delay or overlap risk.
A6: IW14 | B6: 46197 | C6: Future slot
A7: IW15 | B7: 46218 | C7: Future slot

Sheet Task Template
A1: Task Order | B1: Scope | C1: Subcontractor | D1: Default Days | E1: Dependency | F1: Bottleneck Vendor
A2: 1 | B2: Estimate | C2: Willett & Assoc. | D2: 10
A3: 2 | B3: Clearing | C3: Willett & Assoc. | D3: 3 | E3: Estimate
A4: 3 | B4: Site Prep | C4: Willett & Assoc. | D4: 2 | E4: Clearing
A5: 4 | B5: Footer | C5: 3C Concrete | D5: 4 | E5: Site Prep | F5: 3C Concrete
A6: 5 | B6: Block | C6: Julio H | D6: 10 | E6: Footer
A7: 6 | B7: French Drain | C7: Jacob Hayden | D7: 2 | E7: Block
A8: 7 | B8: Insulation Block | C8: Tyler Champion | D8: 2 | E8: Block
A9: 8 | B9: Rock Work | D9: 2 | E9: Insulation Block
A10: 9 | B10: HVAC Pre | C10: Adco | D10: 2 | E10: Rock Work
A11: 10 | B11: Plumbing Pre | C11: Hays | D11: 5 | E11: Rock Work | F11: Hays
A12: 11 | B12: Electrical Pre | C12: Dave Kaler | D12: 2 | E12: Rock Work
A13: 12 | B13: Slab | C13: 3C Concrete | D13: 4 | E13: Plumbing Pre | F13: 3C Concrete
A14: 13 | B14: Framing | C14: Gerardo | D14: 30 | E14: Slab
A15: 14 | B15: Roofing | C15: Rod Smith | D15: 4 | E15: Framing
A16: 15 | B16: Brick | C16: Julio H | D16: 20 | E16: Roofing
A17: 16 | B17: Stone | C17: Julio H | D17: 20 | E17: Roofing
A18: 17 | B18: Siding | C18: Gerardo | D18: 20 | E18: Roofing
A19: 18 | B19: Rough Grade | D19: 2 | E19: Brick
A20: 19 | B20: Irrigation | C20: Ramiro | D20: 2 | E20: Rough Grade
A21: 20 | B21: Finish Grade | C21: Jacob Hayden | D21: 2 | E21: Irrigation
A22: 21 | B22: Landscaping | C22: Jacob Hayden | D22: 2 | E22: Irrigation
A23: 22 | B23: Lawn Seeding | C23: TruGreen | D23: 2 | E23: Finish Grade
A24: 23 | B24: Gutter drains | D24: 2 | E24: Rough Grade
A25: 24 | B25: HVAC Rough | C25: Adco | D25: 5 | E25: Framing
A26: 25 | B26: Plumbing Rough | C26: Hays | D26: 5 | E26: Framing | F26: Hays
A27: 26 | B27: Electrical Rough | C27: Dave Kaler | D27: 10 | E27: Framing
A28: 27 | B28: Insulation Walls | C28: Tyler Champion | D28: 2 | E28: Electrical Rough
A29: 28 | B29: Sheetrock | C29: Bernall Constr. | D29: 15 | E29: Insulation Walls
A30: 29 | B30: Painting Primer | C30: L&L Painting | D30: 3 | E30: Sheetrock
A31: 30 | B31: Garage Doors | C31: Danny Liedecher | D31: 2 | E31: Painting Primer
A32: 31 | B32: Flooring | C32: LW Contracting | D32: 5 | E32: Painting Primer
A33: 32 | B33: Tile Work | C33: LW Contracting | D33: 8 | E33: Painting Primer
A34: 33 | B34: Trim Interior | C34: Matt Thorne | D34: 20 | E34: Flooring | F34: Matt Thorne
A35: 34 | B35: Trim Exterior | C35: Matt Thorne | D35: 2 | E35: Siding | F35: Matt Thorne
A36: 35 | B36: Cabinets | C36: Whittmer | D36: 3 | E36: Flooring
A37: 36 | B37: Countertops | C37: Tate Granit | D37: 2 | E37: Cabinets
A38: 37 | B38: Painting Main | C38: L&L Painting | D38: 10 | E38: Countertops
A39: 38 | B39: Appliances | C39: Dave Kaler | D39: 2 | E39: Countertops
A40: 39 | B40: HVAC Finish | C40: Adco | D40: 2 | E40: Painting Main
...

Sheet Schedule Engine
A1: Seq | B1: Project | C1: Project Start | D1: Task Order | E1: Scope | F1: Subcontractor | G1: Bottleneck Vendor | H1: Dependency | I1: Task Key | J1: Dependency Key | K1: Days | L1: Logic Start | M1: Prev Bottleneck Finish | N1: Calculated Start | O1: Calculated Finish | P1: Delay Days | Q1: Status
A2: 1 | B2: IW10 | C2: =INDEX(Projects!$B$2:$B$100,MATCH(B2,Projects!$A$2:$A$100,0)) -> 46113 | D2: 1 | E2: Estimate | F2: Willett & Assoc. | I2: =B2&"|"&E2 -> IW10|Estimate | J2: =IF(H2="","",B2&"|"&H2) | K2: 10 | L2: =IF(H2="",C2,WORKDAY(INDEX($O$2:$O$2000,MATCH(J2,$I$2:$I$2000,0)),1)) -> 46113 | M2: =IF(G2="","",IFERROR(maxifs($O$2:O1,$G$2:G1,G2),"")) | N2: =IF(G2="",L2,MAX(L2,IF(M2="",L2,WORKDAY(M2,1)))) -> 46113 | O2: =WORKDAY(N2,K2-1) -> 46126 | P2: =MAX(0,NETWORKDAYS(L2,N2)-1) -> 0 | Q2: =IF(P2>0,"BOTTLENECK DELAY","")
A3: 2 | B3: IW10 | C3: =INDEX(Projects!$B$2:$B$100,MATCH(B3,Projects!$A$2:$A$100,0)) -> 46113 | D3: 2 | E3: Clearing | F3: Willett & Assoc. | H3: Estimate | I3: =B3&"|"&E3 -> IW10|Clearing | J3: =IF(H3="","",B3&"|"&H3) -> IW10|Estimate | K3: 3 | L3: =IF(H3="",C3,WORKDAY(INDEX($O$2:$O$2000,MATCH(J3,$I$2:$I$2000,0)),1)) -> 46127 | M3: =IF(G3="","",IFERROR(maxifs($O$2:O2,$G$2:G2,G3),"")) | N3: =IF(G3="",L3,MAX(L3,IF(M3="",L3,WORKDAY(M3,1)))) -> 46127 | O3: =WORKDAY(N3,K3-1) -> 46129 | P3: =MAX(0,NETWORKDAYS(L3,N3)-1) -> 0 | Q3: =IF(P3>0,"BOTTLENECK DELAY","")
A4: 3 | B4: IW10 | C4: =INDEX(Projects!$B$2:$B$100,MATCH(B4,Projects!$A$2:$A$100,0)) -> 46113 | D4: 3 | E4: Site Prep | F4: Willett & Assoc. | H4: Clearing | I4: =B4&"|"&E4 -> IW10|Site Prep | J4: =IF(H4="","",B4&"|"&H4) -> IW10|Clearing | K4: 2 | L4: =IF(H4="",C4,WORKDAY(INDEX($O$2:$O$2000,MATCH(J4,$I$2:$I$2000,0)),1)) -> 46132 | M4: =IF(G4="","",IFERROR(maxifs($O$2:O3,$G$2:G3,G4),"")) | N4: =IF(G4="",L4,MAX(L4,IF(M4="",L4,WORKDAY(M4,1)))) -> 46132 | O4: =WORKDAY(N4,K4-1) -> 46133 | P4: =MAX(0,NETWORKDAYS(L4,N4)-1) -> 0 | Q4: =IF(P4>0,"BOTTLENECK DELAY","")
A5: 4 | B5: IW10 | C5: =INDEX(Projects!$B$2:$B$100,MATCH(B5,Projects!$A$2:$A$100,0)) -> 46113 | D5: 4 | E5: Footer | F5: 3C Concrete | G5: 3C Concrete | H5: Site Prep | I5: =B5&"|"&E5 -> IW10|Footer | J5: =IF(H5="","",B5&"|"&H5) -> IW10|Site Prep | K5: 4 | L5: =IF(H5="",C5,WORKDAY(INDEX($O$2:$O$2000,MATCH(J5,$I$2:$I$2000,0)),1)) -> 46134 | M5: =IF(G5="","",IFERROR(maxifs($O$2:O4,$G$2:G4,G5),"")) | N5: =IF(G5="",L5,MAX(L5,IF(M5="",L5,WORKDAY(M5,1)))) -> 46134 | O5: =WORKDAY(N5,K5-1) -> 46139 | P5: =MAX(0,NETWORKDAYS(L5,N5)-1) -> 0 | Q5: =IF(P5>0,"BOTTLENECK DELAY","")
A6: 5 | B6: IW10 | C6: =INDEX(Projects!$B$2:$B$100,MATCH(B6,Projects!$A$2:$A$100,0)) -> 46113 | D6: 5 | E6: Block | F6: Julio H | H6: Footer | I6: =B6&"|"&E6 -> IW10|Block | J6: =IF(H6="","",B6&"|"&H6) -> IW10|Footer | K6: 10 | L6: =IF(H6="",C6,WORKDAY(INDEX($O$2:$O$2000,MATCH(J6,$I$2:$I$2000,0)),1)) -> 46140 | M6: =IF(G6="","",IFERROR(maxifs($O$2:O5,$G$2:G5,G6),"")) | N6: =IF(G6="",L6,MAX(L6,IF(M6="",L6,WORKDAY(M6,1)))) -> 46140 | O6: =WORKDAY(N6,K6-1) -> 46153 | P6: =MAX(0,NETWORKDAYS(L6,N6)-1) -> 0 | Q6: =IF(P6>0,"BOTTLENECK DELAY","")
A7: 6 | B7: IW10 | C7: =INDEX(Projects!$B$2:$B$100,MATCH(B7,Projects!$A$2:$A$100,0)) -> 46113 | D7: 6 | E7: French Drain | F7: Jacob Hayden | H7: Block | I7: =B7&"|"&E7 -> IW10|French Drain | J7: =IF(H7="","",B7&"|"&H7) -> IW10|Block | K7: 2 | L7: =IF(H7="",C7,WORKDAY(INDEX($O$2:$O$2000,MATCH(J7,$I$2:$I$2000,0)),1)) -> 46154 | M7: =IF(G7="","",IFERROR(maxifs($O$2:O6,$G$2:G6,G7),"")) | N7: =IF(G7="",L7,MAX(L7,IF(M7="",L7,WORKDAY(M7,1)))) -> 46154 | O7: =WORKDAY(N7,K7-1) -> 46155 | P7: =MAX(0,NETWORKDAYS(L7,N7)-1) -> 0 | Q7: =IF(P7>0,"BOTTLENECK DELAY","")
A8: 7 | B8: IW10 | C8: =INDEX(Projects!$B$2:$B$100,MATCH(B8,Projects!$A$2:$A$100,0)) -> 46113 | D8: 7 | E8: Insulation Block | F8: Tyler Champion | H8: Block | I8: =B8&"|"&E8 -> IW10|Insulation Block | J8: =IF(H8="","",B8&"|"&H8) -> IW10|Block | K8: 2 | L8: =IF(H8="",C8,WORKDAY(INDEX($O$2:$O$2000,MATCH(J8,$I$2:$I$2000,0)),1)) -> 46154 | M8: =IF(G8="","",IFERROR(maxifs($O$2:O7,$G$2:G7,G8),"")) | N8: =IF(G8="",L8,MAX(L8,IF(M8="",L8,WORKDAY(M8,1)))) -> 46154 | O8: =WORKDAY(N8,K8-1) -> 46155 | P8: =MAX(0,NETWORKDAYS(L8,N8)-1) -> 0 | Q8: =IF(P8>0,"BOTTLENECK DELAY","")
A9: 8 | B9: IW10 | C9: =INDEX(Projects!$B$2:$B$100,MATCH(B9,Projects!$A$2:$A$100,0)) -> 46113 | D9: 8 | E9: Rock Work | H9: Insulation Block | I9: =B9&"|"&E9 -> IW10|Rock Work | J9: =IF(H9="","",B9&"|"&H9) -> IW10|Insulation Block | K9: 2 | L9: =IF(H9="",C9,WORKDAY(INDEX($O$2:$O$2000,MATCH(J9,$I$2:$I$2000,0)),1)) -> 46156 | M9: =IF(G9="","",IFERROR(maxifs($O$2:O8,$G$2:G8,G9),"")) | N9: =IF(G9="",L9,MAX(L9,IF(M9="",L9,WORKDAY(M9,1)))) -> 46156 | O9: =WORKDAY(N9,K9-1) -> 46157 | P9: =MAX(0,NETWORKDAYS(L9,N9)-1) -> 0 | Q9: =IF(P9>0,"BOTTLENECK DELAY","")
A10: 9 | B10: IW10 | C10: =INDEX(Projects!$B$2:$B$100,MATCH(B10,Projects!$A$2:$A$100,0)) -> 46113 | D10: 9 | E10: HVAC Pre | F10: Adco | H10: Rock Work | I10: =B10&"|"&E10 -> IW10|HVAC Pre | J10: =IF(H10="","",B10&"|"&H10) -> IW10|Rock Work | K10: 2 | L10: =IF(H10="",C10,WORKDAY(INDEX($O$2:$O$2000,MATCH(J10,$I$2:$I$2000,0)),1)) -> 46160 | M10: =IF(G10="","",IFERROR(maxifs($O$2:O9,$G$2:G9,G10),"")) | N10: =IF(G10="",L10,MAX(L10,IF(M10="",L10,WORKDAY(M10,1)))) -> 46160 | O10: =WORKDAY(N10,K10-1) -> 46161 | P10: =MAX(0,NETWORKDAYS(L10,N10)-1) -> 0 | Q10: =IF(P10>0,"BOTTLENECK DELAY","")
A11: 10 | B11: IW10 | C11: =INDEX(Projects!$B$2:$B$100,MATCH(B11,Projects!$A$2:$A$100,0)) -> 46113 | D11: 10 | E11: Plumbing Pre | F11: Hays | G11: Hays | H11: Rock Work | I11: =B11&"|"&E11 -> IW10|Plumbing Pre | J11: =IF(H11="","",B11&"|"&H11) -> IW10|Rock Work | K11: 5 | L11: =IF(H11="",C11,WORKDAY(INDEX($O$2:$O$2000,MATCH(J11,$I$2:$I$2000,0)),1)) -> 46160 | M11: =IF(G11="","",IFERROR(maxifs($O$2:O10,$G$2:G10,G11),"")) | N11: =IF(G11="",L11,MAX(L11,IF(M11="",L11,WORKDAY(M11,1)))) -> 46160 | O11: =WORKDAY(N11,K11-1) -> 46164 | P11: =MAX(0,NETWORKDAYS(L11,N11)-1) -> 0 | Q11: =IF(P11>0,"BOTTLENECK DELAY","")
A12: 11 | B12: IW10 | C12: =INDEX(Projects!$B$2:$B$100,MATCH(B12,Projects!$A$2:$A$100,0)) -> 46113 | D12: 11 | E12: Electrical Pre | F12: Dave Kaler | H12: Rock Work | I12: =B12&"|"&E12 -> IW10|Electrical Pre | J12: =IF(H12="","",B12&"|"&H12) -> IW10|Rock Work | K12: 2 | L12: =IF(H12="",C12,WORKDAY(INDEX($O$2:$O$2000,MATCH(J12,$I$2:$I$2000,0)),1)) -> 46160 | M12: =IF(G12="","",IFERROR(maxifs($O$2:O11,$G$2:G11,G12),"")) | N12: =IF(G12="",L12,MAX(L12,IF(M12="",L12,WORKDAY(M12,1)))) -> 46160 | O12: =WORKDAY(N12,K12-1) -> 46161 | P12: =MAX(0,NETWORKDAYS(L12,N12)-1) -> 0 | Q12: =IF(P12>0,"BOTTLENECK DELAY","")
A13: 12 | B13: IW10 | C13: =INDEX(Projects!$B$2:$B$100,MATCH(B13,Projects!$A$2:$A$100,0)) -> 46113 | D13: 12 | E13: Slab | F13: 3C Concrete | G13: 3C Concrete | H13: Plumbing Pre | I13: =B13&"|"&E13 -> IW10|Slab | J13: =IF(H13="","",B13&"|"&H13) -> IW10|Plumbing Pre | K13: 4 | L13: =IF(H13="",C13,WORKDAY(INDEX($O$2:$O$2000,MATCH(J13,$I$2:$I$2000,0)),1)) -> 46167 | M13: =IF(G13="","",IFERROR(maxifs($O$2:O12,$G$2:G12,G13),"")) | N13: =IF(G13="",L13,MAX(L13,IF(M13="",L13,WORKDAY(M13,1)))) -> 46167 | O13: =WORKDAY(N13,K13-1) -> 46170 | P13: =MAX(0,NETWORKDAYS(L13,N13)-1) -> 0 | Q13: =IF(P13>0,"BOTTLENECK DELAY","")
A14: 13 | B14: IW10 | C14: =INDEX(Projects!$B$2:$B$100,MATCH(B14,Projects!$A$2:$A$100,0)) -> 46113 | D14: 13 | E14: Framing | F14: Gerardo | H14: Slab | I14: =B14&"|"&E14 -> IW10|Framing | J14: =IF(H14="","",B14&"|"&H14) -> IW10|Slab | K14: 30 | L14: =IF(H14="",C14,WORKDAY(INDEX($O$2:$O$2000,MATCH(J14,$I$2:$I$2000,0)),1)) -> 46171 | M14: =IF(G14="","",IFERROR(maxifs($O$2:O13,$G$2:G13,G14),"")) | N14: =IF(G14="",L14,MAX(L14,IF(M14="",L14,WORKDAY(M14,1)))) -> 46171 | O14: =WORKDAY(N14,K14-1) -> 46212 | P14: =MAX(0,NETWORKDAYS(L14,N14)-1) -> 0 | Q14: =IF(P14>0,"BOTTLENECK DELAY","")
A15: 14 | B15: IW10 | C15: =INDEX(Projects!$B$2:$B$100,MATCH(B15,Projects!$A$2:$A$100,0)) -> 46113 | D15: 14 | E15: Roofing | F15: Rod Smith | H15: Framing | I15: =B15&"|"&E15 -> IW10|Roofing | J15: =IF(H15="","",B15&"|"&H15) -> IW10|Framing | K15: 4 | L15: =IF(H15="",C15,WORKDAY(INDEX($O$2:$O$2000,MATCH(J15,$I$2:$I$2000,0)),1)) -> 46213 | M15: =IF(G15="","",IFERROR(maxifs($O$2:O14,$G$2:G14,G15),"")) | N15: =IF(G15="",L15,MAX(L15,IF(M15="",L15,WORKDAY(M15,1)))) -> 46213 | O15: =WORKDAY(N15,K15-1) -> 46218 | P15: =MAX(0,NETWORKDAYS(L15,N15)-1) -> 0 | Q15: =IF(P15>0,"BOTTLENECK DELAY","")
A16: 15 | B16: IW10 | C16: =INDEX(Projects!$B$2:$B$100,MATCH(B16,Projects!$A$2:$A$100,0)) -> 46113 | D16: 15 | E16: Brick | F16: Julio H | H16: Roofing | I16: =B16&"|"&E16 -> IW10|Brick | J16: =IF(H16="","",B16&"|"&H16) -> IW10|Roofing | K16: 20 | L16: =IF(H16="",C16,WORKDAY(INDEX($O$2:$O$2000,MATCH(J16,$I$2:$I$2000,0)),1)) -> 46219 | M16: =IF(G16="","",IFERROR(maxifs($O$2:O15,$G$2:G15,G16),"")) | N16: =IF(G16="",L16,MAX(L16,IF(M16="",L16,WORKDAY(M16,1)))) -> 46219 | O16: =WORKDAY(N16,K16-1) -> 46246 | P16: =MAX(0,NETWORKDAYS(L16,N16)-1) -> 0 | Q16: =IF(P16>0,"BOTTLENECK DELAY","")
A17: 16 | B17: IW10 | C17: =INDEX(Projects!$B$2:$B$100,MATCH(B17,Projects!$A$2:$A$100,0)) -> 46113 | D17: 16 | E17: Stone | F17: Julio H | H17: Roofing | I17: =B17&"|"&E17 -> IW10|Stone | J17: =IF(H17="","",B17&"|"&H17) -> IW10|Roofing | K17: 20 | L17: =IF(H17="",C17,WORKDAY(INDEX($O$2:$O$2000,MATCH(J17,$I$2:$I$2000,0)),1)) -> 46219 | M17: =IF(G17="","",IFERROR(maxifs($O$2:O16,$G$2:G16,G17),"")) | N17: =IF(G17="",L17,MAX(L17,IF(M17="",L17,WORKDAY(M17,1)))) -> 46219 | O17: =WORKDAY(N17,K17-1) -> 46246 | P17: =MAX(0,NETWORKDAYS(L17,N17)-1) -> 0 | Q17: =IF(P17>0,"BOTTLENECK DELAY","")
A18: 17 | B18: IW10 | C18: =INDEX(Projects!$B$2:$B$100,MATCH(B18,Projects!$A$2:$A$100,0)) -> 46113 | D18: 17 | E18: Siding | F18: Gerardo | H18: Roofing | I18: =B18&"|"&E18 -> IW10|Siding | J18: =IF(H18="","",B18&"|"&H18) -> IW10|Roofing | K18: 20 | L18: =IF(H18="",C18,WORKDAY(INDEX($O$2:$O$2000,MATCH(J18,$I$2:$I$2000,0)),1)) -> 46219 | M18: =IF(G18="","",IFERROR(maxifs($O$2:O17,$G$2:G17,G18),"")) | N18: =IF(G18="",L18,MAX(L18,IF(M18="",L18,WORKDAY(M18,1)))) -> 46219 | O18: =WORKDAY(N18,K18-1) -> 46246 | P18: =MAX(0,NETWORKDAYS(L18,N18)-1) -> 0 | Q18: =IF(P18>0,"BOTTLENECK DELAY","")
A19: 18 | B19: IW10 | C19: =INDEX(Projects!$B$2:$B$100,MATCH(B19,Projects!$A$2:$A$100,0)) -> 46113 | D19: 18 | E19: Rough Grade | H19: Brick | I19: =B19&"|"&E19 -> IW10|Rough Grade | J19: =IF(H19="","",B19&"|"&H19) -> IW10|Brick | K19: 2 | L19: =IF(H19="",C19,WORKDAY(INDEX($O$2:$O$2000,MATCH(J19,$I$2:$I$2000,0)),1)) -> 46247 | M19: =IF(G19="","",IFERROR(maxifs($O$2:O18,$G$2:G18,G19),"")) | N19: =IF(G19="",L19,MAX(L19,IF(M19="",L19,WORKDAY(M19,1)))) -> 46247 | O19: =WORKDAY(N19,K19-1) -> 46248 | P19: =MAX(0,NETWORKDAYS(L19,N19)-1) -> 0 | Q19: =IF(P19>0,"BOTTLENECK DELAY","")
A20: 19 | B20: IW10 | C20: =INDEX(Projects!$B$2:$B$100,MATCH(B20,Projects!$A$2:$A$100,0)) -> 46113 | D20: 19 | E20: Irrigation | F20: Ramiro | H20: Rough Grade | I20: =B20&"|"&E20 -> IW10|Irrigation | J20: =IF(H20="","",B20&"|"&H20) -> IW10|Rough Grade | K20: 2 | L20: =IF(H20="",C20,WORKDAY(INDEX($O$2:$O$2000,MATCH(J20,$I$2:$I$2000,0)),1)) -> 46251 | M20: =IF(G20="","",IFERROR(maxifs($O$2:O19,$G$2:G19,G20),"")) | N20: =IF(G20="",L20,MAX(L20,IF(M20="",L20,WORKDAY(M20,1)))) -> 46251 | O20: =WORKDAY(N20,K20-1) -> 46252 | P20: =MAX(0,NETWORKDAYS(L20,N20)-1) -> 0 | Q20: =IF(P20>0,"BOTTLENECK DELAY","")
A21: 20 | B21: IW10 | C21: =INDEX(Projects!$B$2:$B$100,MATCH(B21,Projects!$A$2:$A$100,0)) -> 46113 | D21: 20 | E21: Finish Grade | F21: Jacob Hayden | H21: Irrigation | I21: =B21&"|"&E21 -> IW10|Finish Grade | J21: =IF(H21="","",B21&"|"&H21) -> IW10|Irrigation | K21: 2 | L21: =IF(H21="",C21,WORKDAY(INDEX($O$2:$O$2000,MATCH(J21,$I$2:$I$2000,0)),1)) -> 46253 | M21: =IF(G21="","",IFERROR(maxifs($O$2:O20,$G$2:G20,G21),"")) | N21: =IF(G21="",L21,MAX(L21,IF(M21="",L21,WORKDAY(M21,1)))) -> 46253 | O21: =WORKDAY(N21,K21-1) -> 46254 | P21: =MAX(0,NETWORKDAYS(L21,N21)-1) -> 0 | Q21: =IF(P21>0,"BOTTLENECK DELAY","")
A22: 21 | B22: IW10 | C22: =INDEX(Projects!$B$2:$B$100,MATCH(B22,Projects!$A$2:$A$100,0)) -> 46113 | D22: 21 | E22: Landscaping | F22: Jacob Hayden | H22: Irrigation | I22: =B22&"|"&E22 -> IW10|Landscaping | J22: =IF(H22="","",B22&"|"&H22) -> IW10|Irrigation | K22: 2 | L22: =IF(H22="",C22,WORKDAY(INDEX($O$2:$O$2000,MATCH(J22,$I$2:$I$2000,0)),1)) -> 46253 | M22: =IF(G22="","",IFERROR(maxifs($O$2:O21,$G$2:G21,G22),"")) | N22: =IF(G22="",L22,MAX(L22,IF(M22="",L22,WORKDAY(M22,1)))) -> 46253 | O22: =WORKDAY(N22,K22-1) -> 46254 | P22: =MAX(0,NETWORKDAYS(L22,N22)-1) -> 0 | Q22: =IF(P22>0,"BOTTLENECK DELAY","")
A23: 22 | B23: IW10 | C23: =INDEX(Projects!$B$2:$B$100,MATCH(B23,Projects!$A$2:$A$100,0)) -> 46113 | D23: 22 | E23: Lawn Seeding | F23: TruGreen | H23: Finish Grade | I23: =B23&"|"&E23 -> IW10|Lawn Seeding | J23: =IF(H23="","",B23&"|"&H23) -> IW10|Finish Grade | K23: 2 | L23: =IF(H23="",C23,WORKDAY(INDEX($O$2:$O$2000,MATCH(J23,$I$2:$I$2000,0)),1)) -> 46255 | M23: =IF(G23="","",IFERROR(maxifs($O$2:O22,$G$2:G22,G23),"")) | N23: =IF(G23="",L23,MAX(L23,IF(M23="",L23,WORKDAY(M23,1)))) -> 46255 | O23: =WORKDAY(N23,K23-1) -> 46258 | P23: =MAX(0,NETWORKDAYS(L23,N23)-1) -> 0 | Q23: =IF(P23>0,"BOTTLENECK DELAY","")
A24: 23 | B24: IW10 | C24: =INDEX(Projects!$B$2:$B$100,MATCH(B24,Projects!$A$2:$A$100,0)) -> 46113 | D24: 23 | E24: Gutter drains | H24: Rough Grade | I24: =B24&"|"&E24 -> IW10|Gutter drains | J24: =IF(H24="","",B24&"|"&H24) -> IW10|Rough Grade | K24: 2 | L24: =IF(H24="",C24,WORKDAY(INDEX($O$2:$O$2000,MATCH(J24,$I$2:$I$2000,0)),1)) -> 46251 | M24: =IF(G24="","",IFERROR(maxifs($O$2:O23,$G$2:G23,G24),"")) | N24: =IF(G24="",L24,MAX(L24,IF(M24="",L24,WORKDAY(M24,1)))) -> 46251 | O24: =WORKDAY(N24,K24-1) -> 46252 | P24: =MAX(0,NETWORKDAYS(L24,N24)-1) -> 0 | Q24: =IF(P24>0,"BOTTLENECK DELAY","")
A25: 24 | B25: IW10 | C25: =INDEX(Projects!$B$2:$B$100,MATCH(B25,Projects!$A$2:$A$100,0)) -> 46113 | D25: 24 | E25: HVAC Rough | F25: Adco | H25: Framing | I25: =B25&"|"&E25 -> IW10|HVAC Rough | J25: =IF(H25="","",B25&"|"&H25) -> IW10|Framing | K25: 5 | L25: =IF(H25="",C25,WORKDAY(INDEX($O$2:$O$2000,MATCH(J25,$I$2:$I$2000,0)),1)) -> 46213 | M25: =IF(G25="","",IFERROR(maxifs($O$2:O24,$G$2:G24,G25),"")) | N25: =IF(G25="",L25,MAX(L25,IF(M25="",L25,WORKDAY(M25,1)))) -> 46213 | O25: =WORKDAY(N25,K25-1) -> 46219 | P25: =MAX(0,NETWORKDAYS(L25,N25)-1) -> 0 | Q25: =IF(P25>0,"BOTTLENECK DELAY","")
A26: 25 | B26: IW10 | C26: =INDEX(Projects!$B$2:$B$100,MATCH(B26,Projects!$A$2:$A$100,0)) -> 46113 | D26: 25 | E26: Plumbing Rough | F26: Hays | G26: Hays | H26: Framing | I26: =B26&"|"&E26 -> IW10|Plumbing Rough | J26: =IF(H26="","",B26&"|"&H26) -> IW10|Framing | K26: 5 | L26: =IF(H26="",C26,WORKDAY(INDEX($O$2:$O$2000,MATCH(J26,$I$2:$I$2000,0)),1)) -> 46213 | M26: =IF(G26="","",IFERROR(maxifs($O$2:O25,$G$2:G25,G26),"")) | N26: =IF(G26="",L26,MAX(L26,IF(M26="",L26,WORKDAY(M26,1)))) -> 46213 | O26: =WORKDAY(N26,K26-1) -> 46219 | P26: =MAX(0,NETWORKDAYS(L26,N26)-1) -> 0 | Q26: =IF(P26>0,"BOTTLENECK DELAY","")
A27: 26 | B27: IW10 | C27: =INDEX(Projects!$B$2:$B$100,MATCH(B27,Projects!$A$2:$A$100,0)) -> 46113 | D27: 26 | E27: Electrical Rough | F27: Dave Kaler | H27: Framing | I27: =B27&"|"&E27 -> IW10|Electrical Rough | J27: =IF(H27="","",B27&"|"&H27) -> IW10|Framing | K27: 10 | L27: =IF(H27="",C27,WORKDAY(INDEX($O$2:$O$2000,MATCH(J27,$I$2:$I$2000,0)),1)) -> 46213 | M27: =IF(G27="","",IFERROR(maxifs($O$2:O26,$G$2:G26,G27),"")) | N27: =IF(G27="",L27,MAX(L27,IF(M27="",L27,WORKDAY(M27,1)))) -> 46213 | O27: =WORKDAY(N27,K27-1) -> 46226 | P27: =MAX(0,NETWORKDAYS(L27,N27)-1) -> 0 | Q27: =IF(P27>0,"BOTTLENECK DELAY","")
A28: 27 | B28: IW10 | C28: =INDEX(Projects!$B$2:$B$100,MATCH(B28,Projects!$A$2:$A$100,0)) -> 46113 | D28: 27 | E28: Insulation Walls | F28: Tyler Champion | H28: Electrical Rough | I28: =B28&"|"&E28 -> IW10|Insulation Walls | J28: =IF(H28="","",B28&"|"&H28) -> IW10|Electrical Rough | K28: 2 | L28: =IF(H28="",C28,WORKDAY(INDEX($O$2:$O$2000,MATCH(J28,$I$2:$I$2000,0)),1)) -> 46227 | M28: =IF(G28="","",IFERROR(maxifs($O$2:O27,$G$2:G27,G28),"")) | N28: =IF(G28="",L28,MAX(L28,IF(M28="",L28,WORKDAY(M28,1)))) -> 46227 | O28: =WORKDAY(N28,K28-1) -> 46230 | P28: =MAX(0,NETWORKDAYS(L28,N28)-1) -> 0 | Q28: =IF(P28>0,"BOTTLENECK DELAY","")
A29: 28 | B29: IW10 | C29: =INDEX(Projects!$B$2:$B$100,MATCH(B29,Projects!$A$2:$A$100,0)) -> 46113 | D29: 28 | E29: Sheetrock | F29: Bernall Constr. | H29: Insulation Walls | I29: =B29&"|"&E29 -> IW10|Sheetrock | J29: =IF(H29="","",B29&"|"&H29) -> IW10|Insulation Walls | K29: 15 | L29: =IF(H29="",C29,WORKDAY(INDEX($O$2:$O$2000,MATCH(J29,$I$2:$I$2000,0)),1)) -> 46231 | M29: =IF(G29="","",IFERROR(maxifs($O$2:O28,$G$2:G28,G29),"")) | N29: =IF(G29="",L29,MAX(L29,IF(M29="",L29,WORKDAY(M29,1)))) -> 46231 | O29: =WORKDAY(N29,K29-1) -> 46251 | P29: =MAX(0,NETWORKDAYS(L29,N29)-1) -> 0 | Q29: =IF(P29>0,"BOTTLENECK DELAY","")
A30: 29 | B30: IW10 | C30: =INDEX(Projects!$B$2:$B$100,MATCH(B30,Projects!$A$2:$A$100,0)) -> 46113 | D30: 29 | E30: Painting Primer | F30: L&L Painting | H30: Sheetrock | I30: =B30&"|"&E30 -> IW10|Painting Primer | J30: =IF(H30="","",B30&"|"&H30) -> IW10|Sheetrock | K30: 3 | L30: =IF(H30="",C30,WORKDAY(INDEX($O$2:$O$2000,MATCH(J30,$I$2:$I$2000,0)),1)) -> 46252 | M30: =IF(G30="","",IFERROR(maxifs($O$2:O29,$G$2:G29,G30),"")) | N30: =IF(G30="",L30,MAX(L30,IF(M30="",L30,WORKDAY(M30,1)))) -> 46252 | O30: =WORKDAY(N30,K30-1) -> 46254 | P30: =MAX(0,NETWORKDAYS(L30,N30)-1) -> 0 | Q30: =IF(P30>0,"BOTTLENECK DELAY","")
A31: 30 | B31: IW10 | C31: =INDEX(Projects!$B$2:$B$100,MATCH(B31,Projects!$A$2:$A$100,0)) -> 46113 | D31: 30 | E31: Garage Doors | F31: Danny Liedecher | H31: Painting Primer | I31: =B31&"|"&E31 -> IW10|Garage Doors | J31: =IF(H31="","",B31&"|"&H31) -> IW10|Painting Primer | K31: 2 | L31: =IF(H31="",C31,WORKDAY(INDEX($O$2:$O$2000,MATCH(J31,$I$2:$I$2000,0)),1)) -> 46255 | M31: =IF(G31="","",IFERROR(maxifs($O$2:O30,$G$2:G30,G31),"")) | N31: =IF(G31="",L31,MAX(L31,IF(M31="",L31,WORKDAY(M31,1)))) -> 46255 | O31: =WORKDAY(N31,K31-1) -> 46258 | P31: =MAX(0,NETWORKDAYS(L31,N31)-1) -> 0 | Q31: =IF(P31>0,"BOTTLENECK DELAY","")
A32: 31 | B32: IW10 | C32: =INDEX(Projects!$B$2:$B$100,MATCH(B32,Projects!$A$2:$A$100,0)) -> 46113 | D32: 31 | E32: Flooring | F32: LW Contracting | H32: Painting Primer | I32: =B32&"|"&E32 -> IW10|Flooring | J32: =IF(H32="","",B32&"|"&H32) -> IW10|Painting Primer | K32: 5 | L32: =IF(H32="",C32,WORKDAY(INDEX($O$2:$O$2000,MATCH(J32,$I$2:$I$2000,0)),1)) -> 46255 | M32: =IF(G32="","",IFERROR(maxifs($O$2:O31,$G$2:G31,G32),"")) | N32: =IF(G32="",L32,MAX(L32,IF(M32="",L32,WORKDAY(M32,1)))) -> 46255 | O32: =WORKDAY(N32,K32-1) -> 46261 | P32: =MAX(0,NETWORKDAYS(L32,N32)-1) -> 0 | Q32: =IF(P32>0,"BOTTLENECK DELAY","")
A33: 32 | B33: IW10 | C33: =INDEX(Projects!$B$2:$B$100,MATCH(B33,Projects!$A$2:$A$100,0)) -> 46113 | D33: 32 | E33: Tile Work | F33: LW Contracting | H33: Painting Primer | I33: =B33&"|"&E33 -> IW10|Tile Work | J33: =IF(H33="","",B33&"|"&H33) -> IW10|Painting Primer | K33: 8 | L33: =IF(H33="",C33,WORKDAY(INDEX($O$2:$O$2000,MATCH(J33,$I$2:$I$2000,0)),1)) -> 46255 | M33: =IF(G33="","",IFERROR(maxifs($O$2:O32,$G$2:G32,G33),"")) | N33: =IF(G33="",L33,MAX(L33,IF(M33="",L33,WORKDAY(M33,1)))) -> 46255 | O33: =WORKDAY(N33,K33-1) -> 46266 | P33: =MAX(0,NETWORKDAYS(L33,N33)-1) -> 0 | Q33: =IF(P33>0,"BOTTLENECK DELAY","")
A34: 33 | B34: IW10 | C34: =INDEX(Projects!$B$2:$B$100,MATCH(B34,Projects!$A$2:$A$100,0)) -> 46113 | D34: 33 | E34: Trim Interior | F34: Matt Thorne | G34: Matt Thorne | H34: Flooring | I34: =B34&"|"&E34 -> IW10|Trim Interior | J34: =IF(H34="","",B34&"|"&H34) -> IW10|Flooring | K34: 20 | L34: =IF(H34="",C34,WORKDAY(INDEX($O$2:$O$2000,MATCH(J34,$I$2:$I$2000,0)),1)) -> 46262 | M34: =IF(G34="","",IFERROR(maxifs($O$2:O33,$G$2:G33,G34),"")) | N34: =IF(G34="",L34,MAX(L34,IF(M34="",L34,WORKDAY(M34,1)))) -> 46262 | O34: =WORKDAY(N34,K34-1) -> 46289 | P34: =MAX(0,NETWORKDAYS(L34,N34)-1) -> 0 | Q34: =IF(P34>0,"BOTTLENECK DELAY","")
A35: 34 | B35: IW10 | C35: =INDEX(Projects!$B$2:$B$100,MATCH(B35,Projects!$A$2:$A$100,0)) -> 46113 | D35: 34 | E35: Trim Exterior | F35: Matt Thorne | G35: Matt Thorne | H35: Siding | I35: =B35&"|"&E35 -> IW10|Trim Exterior | J35: =IF(H35="","",B35&"|"&H35) -> IW10|Siding | K35: 2 | L35: =IF(H35="",C35,WORKDAY(INDEX($O$2:$O$2000,MATCH(J35,$I$2:$I$2000,0)),1)) -> 46247 | M35: =IF(G35="","",IFERROR(maxifs($O$2:O34,$G$2:G34,G35),"")) | N35: =IF(G35="",L35,MAX(L35,IF(M35="",L35,WORKDAY(M35,1)))) -> 46247 | O35: =WORKDAY(N35,K35-1) -> 46248 | P35: =MAX(0,NETWORKDAYS(L35,N35)-1) -> 0 | Q35: =IF(P35>0,"BOTTLENECK DELAY","")
A36: 35 | B36: IW10 | C36: =INDEX(Projects!$B$2:$B$100,MATCH(B36,Projects!$A$2:$A$100,0)) -> 46113 | D36: 35 | E36: Cabinets | F36: Whittmer | H36: Flooring | I36: =B36&"|"&E36 -> IW10|Cabinets | J36: =IF(H36="","",B36&"|"&H36) -> IW10|Flooring | K36: 3 | L36: =IF(H36="",C36,WORKDAY(INDEX($O$2:$O$2000,MATCH(J36,$I$2:$I$2000,0)),1)) -> 46262 | M36: =IF(G36="","",IFERROR(maxifs($O$2:O35,$G$2:G35,G36),"")) | N36: =IF(G36="",L36,MAX(L36,IF(M36="",L36,WORKDAY(M36,1)))) -> 46262 | O36: =WORKDAY(N36,K36-1) -> 46266 | P36: =MAX(0,NETWORKDAYS(L36,N36)-1) -> 0 | Q36: =IF(P36>0,"BOTTLENECK DELAY","")
A37: 36 | B37: IW10 | C37: =INDEX(Projects!$B$2:$B$100,MATCH(B37,Projects!$A$2:$A$100,0)) -> 46113 | D37: 36 | E37: Countertops | F37: Tate Granit | H37: Cabinets | I37: =B37&"|"&E37 -> IW10|Countertops | J37: =IF(H37="","",B37&"|"&H37) -> IW10|Cabinets | K37: 2 | L37: =IF(H37="",C37,WORKDAY(INDEX($O$2:$O$2000,MATCH(J37,$I$2:$I$2000,0)),1)) -> 46267 | M37: =IF(G37="","",IFERROR(maxifs($O$2:O36,$G$2:G36,G37),"")) | N37: =IF(G37="",L37,MAX(L37,IF(M37="",L37,WORKDAY(M37,1)))) -> 46267 | O37: =WORKDAY(N37,K37-1) -> 46268 | P37: =MAX(0,NETWORKDAYS(L37,N37)-1) -> 0 | Q37: =IF(P37>0,"BOTTLENECK DELAY","")
A38: 37 | B38: IW10 | C38: =INDEX(Projects!$B$2:$B$100,MATCH(B38,Projects!$A$2:$A$100,0)) -> 46113 | D38: 37 | E38: Painting Main | F38: L&L Painting | H38: Countertops | I38: =B38&"|"&E38 -> IW10|Painting Main | J38: =IF(H38="","",B38&"|"&H38) -> IW10|Countertops | K38: 10 | L38: =IF(H38="",C38,WORKDAY(INDEX($O$2:$O$2000,MATCH(J38,$I$2:$I$2000,0)),1)) -> 46269 | M38: =IF(G38="","",IFERROR(maxifs($O$2:O37,$G$2:G37,G38),"")) | N38: =IF(G38="",L38,MAX(L38,IF(M38="",L38,WORKDAY(M38,1)))) -> 46269 | O38: =WORKDAY(N38,K38-1) -> 46282 | P38: =MAX(0,NETWORKDAYS(L38,N38)-1) -> 0 | Q38: =IF(P38>0,"BOTTLENECK DELAY","")
A39: 38 | B39: IW10 | C39: =INDEX(Projects!$B$2:$B$100,MATCH(B39,Projects!$A$2:$A$100,0)) -> 46113 | D39: 38 | E39: Appliances | F39: Dave Kaler | H39: Countertops | I39: =B39&"|"&E39 -> IW10|Appliances | J39: =IF(H39="","",B39&"|"&H39) -> IW10|Countertops | K39: 2 | L39: =IF(H39="",C39,WORKDAY(INDEX($O$2:$O$2000,MATCH(J39,$I$2:$I$2000,0)),1)) -> 46269 | M39: =IF(G39="","",IFERROR(maxifs($O$2:O38,$G$2:G38,G39),"")) | N39: =IF(G39="",L39,MAX(L39,IF(M39="",L39,WORKDAY(M39,1)))) -> 46269 | O39: =WORKDAY(N39,K39-1) -> 46272 | P39: =MAX(0,NETWORKDAYS(L39,N39)-1) -> 0 | Q39: =IF(P39>0,"BOTTLENECK DELAY","")
A40: 39 | B40: IW10 | C40: =INDEX(Projects!$B$2:$B$100,MATCH(B40,Projects!$A$2:$A$100,0)) -> 46113 | D40: 39 | E40: HVAC Finish | F40: Adco | H40: Painting Main | I40: =B40&"|"&E40 -> IW10|HVAC Finish | J40: =IF(H40="","",B40&"|"&H40) -> IW10|Painting Main | K40: 2 | L40: =IF(H40="",C40,WORKDAY(INDEX($O$2:$O$2000,MATCH(J40,$I$2:$I$2000,0)),1)) -> 46283 | M40: =IF(G40="","",IFERROR(maxifs($O$2:O39,$G$2:G39,G40),"")) | N40: =IF(G40="",L40,MAX(L40,IF(M40="",L40,WORKDAY(M40,1)))) -> 46283 | O40: =WORKDAY(N40,K40-1) -> 46286 | P40: =MAX(0,NETWORKDAYS(L40,N40)-1) -> 0 | Q40: =IF(P40>0,"BOTTLENECK DELAY","")
...

Sheet Engine Gantt
A1: Project | B1: Scope | C1: Subcontractor | D1: Bottleneck Vendor | E1: Start | F1: Finish | G1: Days | H1: Delay | I1: 46113 | J1: 46114 | K1: 46115 | L1: 46116 | M1: 46117 | N1: 46118 | O1: 46119 | P1: 46120 | Q1: 46121 | R1: 46122 | S1: 46123 | T1: 46124 | U1: 46125 | V1: 46126 | W1: 46127 | X1: 46128 | Y1: 46129 | Z1: 46130 | AA1: 46131 | AB1: 46132 | AC1: 46133 | AD1: 46134 | AE1: 46135 | AF1: 46136 | AG1: 46137 | AH1: 46138 | AI1: 46139 | AJ1: 46140 | AK1: 46141 | AL1: 46142 | AM1: 46143 | AN1: 46144 | AO1: 46145 | AP1: 46146 | AQ1: 46147 | AR1: 46148 | AS1: 46149 | AT1: 46150 | AU1: 46151 | AV1: 46152 | AW1: 46153 | AX1: 46154 | AY1: 46155 | AZ1: 46156 | BA1: 46157 | BB1: 46158 | BC1: 46159 | BD1: 46160 | BE1: 46161 | BF1: 46162 | BG1: 46163 | BH1: 46164 | BI1: 46165 | BJ1: 46166 | BK1: 46167 | BL1: 46168 | BM1: 46169 | BN1: 46170 | BO1: 46171 | BP1: 46172 | BQ1: 46173 | BR1: 46174 | BS1: 46175 | BT1: 46176 | BU1: 46177 | BV1: 46178 | BW1: 46179 | BX1: 46180 | BY1: 46181 | BZ1: 46182 | CA1: 46183 | CB1: 46184 | CC1: 46185 | CD1: 46186 | CE1: 46187 | CF1: 46188 | CG1: 46189 | CH1: 46190 | CI1: 46191 | CJ1: 46192 | CK1: 46193 | CL1: 46194 | CM1: 46195 | CN1: 46196 | CO1: 46197 | CP1: 46198 | CQ1: 46199 | CR1: 46200 | CS1: 46201 | CT1: 46202 | CU1: 46203 | CV1: 46204 | CW1: 46205 | CX1: 46206 | CY1: 46207 | CZ1: 46208 | DA1: 46209 | DB1: 46210 | DC1: 46211 | DD1: 46212 | DE1: 46213 | DF1: 46214 | DG1: 46215 | DH1: 46216 | DI1: 46217 | DJ1: 46218 | DK1: 46219 | DL1: 46220 | DM1: 46221 | DN1: 46222 | DO1: 46223 | DP1: 46224 | DQ1: 46225 | DR1: 46226 | DS1: 46227 | DT1: 46228 | DU1: 46229 | DV1: 46230 | DW1: 46231 | DX1: 46232 | DY1: 46233 | DZ1: 46234 | EA1: 46235 | EB1: 46236 | EC1: 46237 | ED1: 46238 | EE1: 46239 | EF1: 46240 | EG1: 46241 | EH1: 46242 | EI1: 46243 | EJ1: 46244 | EK1: 46245 | EL1: 46246 | EM1: 46247 | EN1: 46248 | EO1: 46249 | EP1: 46250 | EQ1: 46251 | ER1: 46252 | ES1: 46253 | ET1: 46254 | EU1: 46255 | EV1: 46256 | EW1: 46257 | EX1: 46258 | EY1: 46259 | EZ1: 46260 | FA1: 46261 | FB1: 46262 | FC1: 46263 | FD1: 46264 | FE1: 46265 | FF1: 46266 | FG1: 46267 | FH1: 46268 | FI1: 46269 | FJ1: 46270 | FK1: 46271 | FL1: 46272 | FM1: 46273 | FN1: 46274 | FO1: 46275 | FP1: 46276 | FQ1: 46277 | FR1: 46278 | FS1: 46279 | FT1: 46280 | FU1: 46281 | FV1: 46282 | FW1: 46283 | FX1: 46284 | FY1: 46285 | FZ1: 46286 | GA1: 46287 | GB1: 46288 | GC1: 46289 | GD1: 46290 | GE1: 46291 | GF1: 46292 | GG1: 46293 | GH1: 46294 | GI1: 46295 | GJ1: 46296 | GK1: 46297 | GL1: 46298 | GM1: 46299 | GN1: 46300 | GO1: 46301 | GP1: 46302 | GQ1: 46303 | GR1: 46304 | GS1: 46305 | GT1: 46306 | GU1: 46307 | GV1: 46308 | GW1: 46309 | GX1: 46310 | GY1: 46311 | GZ1: 46312 | HA1: 46313 | HB1: 46314 | HC1: 46315 | HD1: 46316 | HE1: 46317 | HF1: 46318 | HG1: 46319 | HH1: 46320 | HI1: 46321 | HJ1: 46322 | HK1: 46323 | HL1: 46324 | HM1: 46325 | HN1: 46326 | HO1: 46327 | HP1: 46328 | HQ1: 46329 | HR1: 46330 | HS1: 46331 | HT1: 46332
I2: W | J2: T | K2: F | L2: S | M2: S | N2: M | O2: T | P2: W | Q2: T | R2: F | S2: S | T2: S | U2: M | V2: T | W2: W | X2: T | Y2: F | Z2: S | AA2: S | AB2: M | AC2: T | AD2: W | AE2: T | AF2: F | AG2: S | AH2: S | AI2: M | AJ2: T | AK2: W | AL2: T | AM2: F | AN2: S | AO2: S | AP2: M | AQ2: T | AR2: W | AS2: T | AT2: F | AU2: S | AV2: S | AW2: M | AX2: T | AY2: W | AZ2: T | BA2: F | BB2: S | BC2: S | BD2: M | BE2: T | BF2: W | BG2: T | BH2: F | BI2: S | BJ2: S | BK2: M | BL2: T | BM2: W | BN2: T | BO2: F | BP2: S | BQ2: S | BR2: M | BS2: T | BT2: W | BU2: T | BV2: F | BW2: S | BX2: S | BY2: M | BZ2: T | CA2: W | CB2: T | CC2: F | CD2: S | CE2: S | CF2: M | CG2: T | CH2: W | CI2: T | CJ2: F | CK2: S | CL2: S | CM2: M | CN2: T | CO2: W | CP2: T | CQ2: F | CR2: S | CS2: S | CT2: M | CU2: T | CV2: W | CW2: T | CX2: F | CY2: S | CZ2: S | DA2: M | DB2: T | DC2: W | DD2: T | DE2: F | DF2: S | DG2: S | DH2: M | DI2: T | DJ2: W | DK2: T | DL2: F | DM2: S | DN2: S | DO2: M | DP2: T | DQ2: W | DR2: T | DS2: F | DT2: S | DU2: S | DV2: M | DW2: T | DX2: W | DY2: T | DZ2: F | EA2: S | EB2: S | EC2: M | ED2: T | EE2: W | EF2: T | EG2: F | EH2: S | EI2: S | EJ2: M | EK2: T | EL2: W | EM2: T | EN2: F | EO2: S | EP2: S | EQ2: M | ER2: T | ES2: W | ET2: T | EU2: F | EV2: S | EW2: S | EX2: M | EY2: T | EZ2: W | FA2: T | FB2: F | FC2: S | FD2: S | FE2: M | FF2: T | FG2: W | FH2: T | FI2: F | FJ2: S | FK2: S | FL2: M | FM2: T | FN2: W | FO2: T | FP2: F | FQ2: S | FR2: S | FS2: M | FT2: T | FU2: W | FV2: T | FW2: F | FX2: S | FY2: S | FZ2: M | GA2: T | GB2: W | GC2: T | GD2: F | GE2: S | GF2: S | GG2: M | GH2: T | GI2: W | GJ2: T | GK2: F | GL2: S | GM2: S | GN2: M | GO2: T | GP2: W | GQ2: T | GR2: F | GS2: S | GT2: S | GU2: M | GV2: T | GW2: W | GX2: T | GY2: F | GZ2: S | HA2: S | HB2: M | HC2: T | HD2: W | HE2: T | HF2: F | HG2: S | HH2: S | HI2: M | HJ2: T | HK2: W | HL2: T | HM2: F | HN2: S | HO2: S | HP2: M | HQ2: T | HR2: W | HS2: T | HT2: F
A3: ='Schedule Engine'!B2 -> IW10 | B3: ='Schedule Engine'!E2 -> Estimate | C3: ='Schedule Engine'!F2 -> Willett & Assoc. | D3: ='Schedule Engine'!G2 -> 0 | E3: ='Schedule Engine'!N2 -> 46113 | F3: ='Schedule Engine'!O2 -> 46126 | G3: ='Schedule Engine'!K2 -> 10 | H3: ='Schedule Engine'!P2 -> 0
A4: ='Schedule Engine'!B3 -> IW10 | B4: ='Schedule Engine'!E3 -> Clearing | C4: ='Schedule Engine'!F3 -> Willett & Assoc. | D4: ='Schedule Engine'!G3 -> 0 | E4: ='Schedule Engine'!N3 -> 46127 | F4: ='Schedule Engine'!O3 -> 46129 | G4: ='Schedule Engine'!K3 -> 3 | H4: ='Schedule Engine'!P3 -> 0
A5: ='Schedule Engine'!B4 -> IW10 | B5: ='Schedule Engine'!E4 -> Site Prep | C5: ='Schedule Engine'!F4 -> Willett & Assoc. | D5: ='Schedule Engine'!G4 -> 0 | E5: ='Schedule Engine'!N4 -> 46132 | F5: ='Schedule Engine'!O4 -> 46133 | G5: ='Schedule Engine'!K4 -> 2 | H5: ='Schedule Engine'!P4 -> 0
A6: ='Schedule Engine'!B5 -> IW10 | B6: ='Schedule Engine'!E5 -> Footer | C6: ='Schedule Engine'!F5 -> 3C Concrete | D6: ='Schedule Engine'!G5 -> 3C Concrete | E6: ='Schedule Engine'!N5 -> 46134 | F6: ='Schedule Engine'!O5 -> 46139 | G6: ='Schedule Engine'!K5 -> 4 | H6: ='Schedule Engine'!P5 -> 0
A7: ='Schedule Engine'!B6 -> IW10 | B7: ='Schedule Engine'!E6 -> Block | C7: ='Schedule Engine'!F6 -> Julio H | D7: ='Schedule Engine'!G6 -> 0 | E7: ='Schedule Engine'!N6 -> 46140 | F7: ='Schedule Engine'!O6 -> 46153 | G7: ='Schedule Engine'!K6 -> 10 | H7: ='Schedule Engine'!P6 -> 0
A8: ='Schedule Engine'!B7 -> IW10 | B8: ='Schedule Engine'!E7 -> French Drain | C8: ='Schedule Engine'!F7 -> Jacob Hayden | D8: ='Schedule Engine'!G7 -> 0 | E8: ='Schedule Engine'!N7 -> 46154 | F8: ='Schedule Engine'!O7 -> 46155 | G8: ='Schedule Engine'!K7 -> 2 | H8: ='Schedule Engine'!P7 -> 0
A9: ='Schedule Engine'!B8 -> IW10 | B9: ='Schedule Engine'!E8 -> Insulation Block | C9: ='Schedule Engine'!F8 -> Tyler Champion | D9: ='Schedule Engine'!G8 -> 0 | E9: ='Schedule Engine'!N8 -> 46154 | F9: ='Schedule Engine'!O8 -> 46155 | G9: ='Schedule Engine'!K8 -> 2 | H9: ='Schedule Engine'!P8 -> 0
A10: ='Schedule Engine'!B9 -> IW10 | B10: ='Schedule Engine'!E9 -> Rock Work | C10: ='Schedule Engine'!F9 -> 0 | D10: ='Schedule Engine'!G9 -> 0 | E10: ='Schedule Engine'!N9 -> 46156 | F10: ='Schedule Engine'!O9 -> 46157 | G10: ='Schedule Engine'!K9 -> 2 | H10: ='Schedule Engine'!P9 -> 0
A11: ='Schedule Engine'!B10 -> IW10 | B11: ='Schedule Engine'!E10 -> HVAC Pre | C11: ='Schedule Engine'!F10 -> Adco | D11: ='Schedule Engine'!G10 -> 0 | E11: ='Schedule Engine'!N10 -> 46160 | F11: ='Schedule Engine'!O10 -> 46161 | G11: ='Schedule Engine'!K10 -> 2 | H11: ='Schedule Engine'!P10 -> 0
A12: ='Schedule Engine'!B11 -> IW10 | B12: ='Schedule Engine'!E11 -> Plumbing Pre | C12: ='Schedule Engine'!F11 -> Hays | D12: ='Schedule Engine'!G11 -> Hays | E12: ='Schedule Engine'!N11 -> 46160 | F12: ='Schedule Engine'!O11 -> 46164 | G12: ='Schedule Engine'!K11 -> 5 | H12: ='Schedule Engine'!P11 -> 0
A13: ='Schedule Engine'!B12 -> IW10 | B13: ='Schedule Engine'!E12 -> Electrical Pre | C13: ='Schedule Engine'!F12 -> Dave Kaler | D13: ='Schedule Engine'!G12 -> 0 | E13: ='Schedule Engine'!N12 -> 46160 | F13: ='Schedule Engine'!O12 -> 46161 | G13: ='Schedule Engine'!K12 -> 2 | H13: ='Schedule Engine'!P12 -> 0
A14: ='Schedule Engine'!B13 -> IW10 | B14: ='Schedule Engine'!E13 -> Slab | C14: ='Schedule Engine'!F13 -> 3C Concrete | D14: ='Schedule Engine'!G13 -> 3C Concrete | E14: ='Schedule Engine'!N13 -> 46167 | F14: ='Schedule Engine'!O13 -> 46170 | G14: ='Schedule Engine'!K13 -> 4 | H14: ='Schedule Engine'!P13 -> 0
... A266: ='Schedule Engine'!B265 -> IW15 | B266: ='Schedule Engine'!E265 -> Cleaning | C266: ='Schedule Engine'!F265 -> Angies Cleaning | D266: ='Schedule Engine'!G265 -> 0 | E266: ='Schedule Engine'!N265 -> 46401 | F266: ='Schedule Engine'!O265 -> 46405 | G266: ='Schedule Engine'!K265 -> 3 | H266: ='Schedule Engine'!P265 -> 0

Sheet Bottleneck Load
A1: Bottleneck Vendor | B1: Capacity | C1: 46113 | D1: 46114 | E1: 46115 | F1: 46116 | G1: 46117 | H1: 46118 | I1: 46119 | J1: 46120 | K1: 46121 | L1: 46122 | M1: 46123 | N1: 46124 | O1: 46125 | P1: 46126 | Q1: 46127 | R1: 46128 | S1: 46129 | T1: 46130 | U1: 46131 | V1: 46132 | W1: 46133 | X1: 46134 | Y1: 46135 | Z1: 46136 | AA1: 46137 | AB1: 46138 | AC1: 46139 | AD1: 46140 | AE1: 46141 | AF1: 46142 | AG1: 46143 | AH1: 46144 | AI1: 46145 | AJ1: 46146 | AK1: 46147 | AL1: 46148 | AM1: 46149 | AN1: 46150 | AO1: 46151 | AP1: 46152 | AQ1: 46153 | AR1: 46154 | AS1: 46155 | AT1: 46156 | AU1: 46157 | AV1: 46158 | AW1: 46159 | AX1: 46160 | AY1: 46161 | AZ1: 46162 | BA1: 46163 | BB1: 46164 | BC1: 46165 | BD1: 46166 | BE1: 46167 | BF1: 46168 | BG1: 46169 | BH1: 46170 | BI1: 46171 | BJ1: 46172 | BK1: 46173 | BL1: 46174 | BM1: 46175 | BN1: 46176 | BO1: 46177 | BP1: 46178 | BQ1: 46179 | BR1: 46180 | BS1: 46181 | BT1: 46182 | BU1: 46183 | BV1: 46184 | BW1: 46185 | BX1: 46186 | BY1: 46187 | BZ1: 46188 | CA1: 46189 | CB1: 46190 | CC1: 46191 | CD1: 46192 | CE1: 46193 | CF1: 46194 | CG1: 46195 | CH1: 46196 | CI1: 46197 | CJ1: 46198 | CK1: 46199 | CL1: 46200 | CM1: 46201 | CN1: 46202 | CO1: 46203 | CP1: 46204 | CQ1: 46205 | CR1: 46206 | CS1: 46207 | CT1: 46208 | CU1: 46209 | CV1: 46210 | CW1: 46211 | CX1: 46212 | CY1: 46213 | CZ1: 46214 | DA1: 46215 | DB1: 46216 | DC1: 46217 | DD1: 46218 | DE1: 46219 | DF1: 46220 | DG1: 46221 | DH1: 46222 | DI1: 46223 | DJ1: 46224 | DK1: 46225 | DL1: 46226 | DM1: 46227 | DN1: 46228 | DO1: 46229 | DP1: 46230 | DQ1: 46231 | DR1: 46232 | DS1: 46233 | DT1: 46234 | DU1: 46235 | DV1: 46236 | DW1: 46237 | DX1: 46238 | DY1: 46239 | DZ1: 46240 | EA1: 46241 | EB1: 46242 | EC1: 46243 | ED1: 46244 | EE1: 46245 | EF1: 46246 | EG1: 46247 | EH1: 46248 | EI1: 46249 | EJ1: 46250 | EK1: 46251 | EL1: 46252 | EM1: 46253 | EN1: 46254 | EO1: 46255 | EP1: 46256 | EQ1: 46257 | ER1: 46258 | ES1: 46259 | ET1: 46260 | EU1: 46261 | EV1: 46262 | EW1: 46263 | EX1: 46264 | EY1: 46265 | EZ1: 46266 | FA1: 46267 | FB1: 46268 | FC1: 46269 | FD1: 46270 | FE1: 46271 | FF1: 46272 | FG1: 46273 | FH1: 46274 | FI1: 46275 | FJ1: 46276 | FK1: 46277 | FL1: 46278 | FM1: 46279 | FN1: 46280 | FO1: 46281 | FP1: 46282 | FQ1: 46283 | FR1: 46284 | FS1: 46285 | FT1: 46286 | FU1: 46287 | FV1: 46288 | FW1: 46289 | FX1: 46290 | FY1: 46291 | FZ1: 46292 | GA1: 46293 | GB1: 46294 | GC1: 46295 | GD1: 46296 | GE1: 46297 | GF1: 46298 | GG1: 46299 | GH1: 46300 | GI1: 46301 | GJ1: 46302 | GK1: 46303 | GL1: 46304 | GM1: 46305 | GN1: 46306 | GO1: 46307 | GP1: 46308 | GQ1: 46309 | GR1: 46310 | GS1: 46311 | GT1: 46312 | GU1: 46313 | GV1: 46314 | GW1: 46315 | GX1: 46316 | GY1: 46317 | GZ1: 46318 | HA1: 46319 | HB1: 46320 | HC1: 46321 | HD1: 46322 | HE1: 46323 | HF1: 46324 | HG1: 46325 | HH1: 46326 | HI1: 46327 | HJ1: 46328 | HK1: 46329 | HL1: 46330 | HM1: 46331 | HN1: 46332
A2: 3C Concrete | B2: 1 | C2: =COUNTIFS('Schedule Engine'!$G:$G,$A2,'Schedule Engine'!$N:$N,"<="&C$1,'Schedule Engine'!$O:$O,">="&C$1) -> 0 | D2: =COUNTIFS('Schedule Engine'!$G:$G,$A2,'Schedule Engine'!$N:$N,"<="&D$1,'Schedule Engine'!$O:$O,">="&D$1) -> 0 | E2: =COUNTIFS('Schedule Engine'!$G:$G,$A2,'Schedule Engine'!$N:$N,"<="&E$1,'Schedule Engine'!$O:$O,">="&E$1) -> 0 | F2: =COUNTIFS('Schedule Engine'!$G:$G,$A2,'Schedule Engine'!$N:$N,"<="&F$1,'Schedule Engine'!$O:$O,">="&F$1) -> 0 | G2: =COUNTIFS('Schedule Engine'!$G:$G,$A2,'Schedule Engine'!$N:$N,"<="&G$1,'Schedule Engine'!$O:$O,">="&G$1) -> 0 | H2: =COUNTIFS('Schedule Engine'!$G:$G,$A2,'Schedule Engine'!$N:$N,"<="&H$1,'Schedule Engine'!$O:$O,">="&H$1) -> 0 | I2: =COUNTIFS('Schedule Engine'!$G:$G,$A2,'Schedule Engine'!$N:$N,"<="&I$1,'Schedule Engine'!$O:$O,">="&I$1) -> 0 | J2: =COUNTIFS('Schedule Engine'!$G:$G,$A2,'Schedule Engine'!$N:$N,"<="&J$1,'Schedule Engine'!$O:$O,">="&J$1) -> 0 | ... HN2: =COUNTIFS('Schedule Engine'!$G:$G,$A2,'Schedule Engine'!$N:$N,"<="&HN$1,'Schedule Engine'!$O:$O,">="&HN$1) -> 0
A3: Hays | B3: 1 | C3: =COUNTIFS('Schedule Engine'!$G:$G,$A3,'Schedule Engine'!$N:$N,"<="&C$1,'Schedule Engine'!$O:$O,">="&C$1) -> 0 | D3: =COUNTIFS('Schedule Engine'!$G:$G,$A3,'Schedule Engine'!$N:$N,"<="&D$1,'Schedule Engine'!$O:$O,">="&D$1) -> 0 | E3: =COUNTIFS('Schedule Engine'!$G:$G,$A3,'Schedule Engine'!$N:$N,"<="&E$1,'Schedule Engine'!$O:$O,">="&E$1) -> 0 | F3: =COUNTIFS('Schedule Engine'!$G:$G,$A3,'Schedule Engine'!$N:$N,"<="&F$1,'Schedule Engine'!$O:$O,">="&F$1) -> 0 | G3: =COUNTIFS('Schedule Engine'!$G:$G,$A3,'Schedule Engine'!$N:$N,"<="&G$1,'Schedule Engine'!$O:$O,">="&G$1) -> 0 | H3: =COUNTIFS('Schedule Engine'!$G:$G,$A3,'Schedule Engine'!$N:$N,"<="&H$1,'Schedule Engine'!$O:$O,">="&H$1) -> 0 | I3: =COUNTIFS('Schedule Engine'!$G:$G,$A3,'Schedule Engine'!$N:$N,"<="&I$1,'Schedule Engine'!$O:$O,">="&I$1) -> 0 | J3: =COUNTIFS('Schedule Engine'!$G:$G,$A3,'Schedule Engine'!$N:$N,"<="&J$1,'Schedule Engine'!$O:$O,">="&J$1) -> 0 | ... HN3: =COUNTIFS('Schedule Engine'!$G:$G,$A3,'Schedule Engine'!$N:$N,"<="&HN$1,'Schedule Engine'!$O:$O,">="&HN$1) -> 1
A4: Matt Thorne | B4: 1 | C4: =COUNTIFS('Schedule Engine'!$G:$G,$A4,'Schedule Engine'!$N:$N,"<="&C$1,'Schedule Engine'!$O:$O,">="&C$1) -> 0 | D4: =COUNTIFS('Schedule Engine'!$G:$G,$A4,'Schedule Engine'!$N:$N,"<="&D$1,'Schedule Engine'!$O:$O,">="&D$1) -> 0 | E4: =COUNTIFS('Schedule Engine'!$G:$G,$A4,'Schedule Engine'!$N:$N,"<="&E$1,'Schedule Engine'!$O:$O,">="&E$1) -> 0 | F4: =COUNTIFS('Schedule Engine'!$G:$G,$A4,'Schedule Engine'!$N:$N,"<="&F$1,'Schedule Engine'!$O:$O,">="&F$1) -> 0 | G4: =COUNTIFS('Schedule Engine'!$G:$G,$A4,'Schedule Engine'!$N:$N,"<="&G$1,'Schedule Engine'!$O:$O,">="&G$1) -> 0 | H4: =COUNTIFS('Schedule Engine'!$G:$G,$A4,'Schedule Engine'!$N:$N,"<="&H$1,'Schedule Engine'!$O:$O,">="&H$1) -> 0 | I4: =COUNTIFS('Schedule Engine'!$G:$G,$A4,'Schedule Engine'!$N:$N,"<="&I$1,'Schedule Engine'!$O:$O,">="&I$1) -> 0 | J4: =COUNTIFS('Schedule Engine'!$G:$G,$A4,'Schedule Engine'!$N:$N,"<="&J$1,'Schedule Engine'!$O:$O,">="&J$1) -> 0 | ... HN4: =COUNTIFS('Schedule Engine'!$G:$G,$A4,'Schedule Engine'!$N:$N,"<="&HN$1,'Schedule Engine'!$O:$O,">="&HN$1) -> 2
